[2024-04-23 01:23:47,130] {taskinstance.py:1159} INFO - Dependencies all met for <TaskInstance: meu_primeiro_dag.cria_pasta scheduled__2024-04-22T00:00:00+00:00 [queued]>
[2024-04-23 01:23:47,136] {taskinstance.py:1159} INFO - Dependencies all met for <TaskInstance: meu_primeiro_dag.cria_pasta scheduled__2024-04-22T00:00:00+00:00 [queued]>
[2024-04-23 01:23:47,136] {taskinstance.py:1356} INFO - 
--------------------------------------------------------------------------------
[2024-04-23 01:23:47,136] {taskinstance.py:1357} INFO - Starting attempt 1 of 1
[2024-04-23 01:23:47,136] {taskinstance.py:1358} INFO - 
--------------------------------------------------------------------------------
[2024-04-23 01:23:47,147] {taskinstance.py:1377} INFO - Executing <Task(BashOperator): cria_pasta> on 2024-04-22 00:00:00+00:00
[2024-04-23 01:23:47,149] {standard_task_runner.py:52} INFO - Started process 113001 to run task
[2024-04-23 01:23:47,151] {standard_task_runner.py:79} INFO - Running: ['airflow', 'tasks', 'run', 'meu_primeiro_dag', 'cria_pasta', 'scheduled__2024-04-22T00:00:00+00:00', '--job-id', '5', '--raw', '--subdir', 'DAGS_FOLDER/meu_primeiro_dag.py', '--cfg-path', '/tmp/tmp2iv26moy', '--error-file', '/tmp/tmphrxk3v9t']
[2024-04-23 01:23:47,151] {standard_task_runner.py:80} INFO - Job 5: Subtask cria_pasta
[2024-04-23 01:23:47,175] {task_command.py:370} INFO - Running <TaskInstance: meu_primeiro_dag.cria_pasta scheduled__2024-04-22T00:00:00+00:00 [running]> on host URATIC9519.RIOBRANCOPETROLEO
[2024-04-23 01:23:47,208] {taskinstance.py:1569} INFO - Exporting the following env vars:
AIRFLOW_CTX_DAG_OWNER=airflow
AIRFLOW_CTX_DAG_ID=meu_primeiro_dag
AIRFLOW_CTX_TASK_ID=cria_pasta
AIRFLOW_CTX_EXECUTION_DATE=2024-04-22T00:00:00+00:00
AIRFLOW_CTX_TRY_NUMBER=1
AIRFLOW_CTX_DAG_RUN_ID=scheduled__2024-04-22T00:00:00+00:00
[2024-04-23 01:23:47,208] {subprocess.py:62} INFO - Tmp dir root location: 
 /tmp
[2024-04-23 01:23:47,209] {subprocess.py:74} INFO - Running command: ['bash', '-c', 'mkdir-p "../pasta" ']
[2024-04-23 01:23:47,214] {subprocess.py:85} INFO - Output:
[2024-04-23 01:23:47,215] {subprocess.py:92} INFO - bash: linha 1: mkdir-p: comando n√£o encontrado
[2024-04-23 01:23:47,215] {subprocess.py:96} INFO - Command exited with return code 127
[2024-04-23 01:23:47,222] {taskinstance.py:1889} ERROR - Task failed with exception
Traceback (most recent call last):
  File "/home/enrico/Documentos/backup/AULA/Alura/Engenharia de dados/projeto_airflow/airflowalura/venv/lib/python3.9/site-packages/airflow/operators/bash.py", line 194, in execute
    raise AirflowException(
airflow.exceptions.AirflowException: Bash command failed. The command returned a non-zero exit code 127.
[2024-04-23 01:23:47,223] {taskinstance.py:1395} INFO - Marking task as FAILED. dag_id=meu_primeiro_dag, task_id=cria_pasta, execution_date=20240422T000000, start_date=20240423T042347, end_date=20240423T042347
[2024-04-23 01:23:47,233] {standard_task_runner.py:92} ERROR - Failed to execute job 5 for task cria_pasta (Bash command failed. The command returned a non-zero exit code 127.; 113001)
[2024-04-23 01:23:47,242] {local_task_job.py:156} INFO - Task exited with return code 1
[2024-04-23 01:23:47,255] {local_task_job.py:273} INFO - 0 downstream tasks scheduled from follow-on schedule check
